<html><header><title>.NET Remoting hosted in IIS return RemotingException</title></header><body><div style='float:right'><a href='http://cslanet.com'><img src='https://github.com/MarimerLLC/csla/raw/master/Support/Logos/csla%20win8_compact_s.png'/></a></div><p><h1>.NET Remoting hosted in IIS return RemotingException</h1><span style='font-size:small'>Old forum URL: forums.lhotka.net/forums/t/3634.aspx</span></p><hr><div style='padding:0 15 3 15;background-color:powderblue'><h2>vasil posted on Tuesday, October 02, 2007</h2><P><FONT face="Courier New" size=2>Hi,<BR></FONT><FONT face="Courier New" size=2>I'm using remote data portal using .NET Remoting hosted in IIS.<BR>Sometimes when I'm trying to update data using Win client installed on machine (*) different that IIS host I've received a message like this:</FONT></P>
<P><FONT face="Courier New" size=2>================<BR><FONT>System.Runtime.Remoting.RemotingException: Server encountered an internal error. For more information, turn off customErrors in the server's .config </FONT></FONT></P>
<P><FONT face="Courier New" size=2>file.<BR>Server stack trace: </FONT></P>
<P><FONT face="Courier New" size=2>Exception rethrown at [0]: <BR>&nbsp;&nbsp; at System.Runtime.Remoting.Proxies.RealProxy.HandleReturnMessage(IMessage reqMsg, IMessage retMsg)<BR>&nbsp;&nbsp; at System.Runtime.Remoting.Proxies.RealProxy.PrivateInvoke(MessageData&amp; msgData, Int32 type)<BR>&nbsp;&nbsp; at Csla.Server.IDataPortalServer.Update(Object obj, DataPortalContext context)<BR>&nbsp;&nbsp; at Csla.DataPortalClient.RemotingProxy.Update(Object obj, DataPortalContext context) in C:\Dev\Resources\Books\csla20vb-2.1.4-070223</FONT></P>
<P><FONT face="Courier New" size=2>\csla20vb\csla20vb\Csla\DataPortal\Client\RemotingProxy.vb:line 130<BR>&nbsp;&nbsp; at Csla.DataPortal.Update(Object obj) in C:\Dev\Resources\Books\csla20vb-2.1.4-070223\csla20vb\csla20vb\Csla\DataPortal\Client\DataPortal.vb:line 324<BR>&nbsp;&nbsp; at Csla.DataPortal.Update[T](T obj) in C:\Dev\Resources\Books\csla20vb-2.1.4-070223\csla20vb\csla20vb\Csla\DataPortal\Client\DataPortal.vb:line 273<BR>&nbsp;&nbsp; at Csla.BusinessBase`1.Save() in C:\Dev\Resources\Books\csla20vb-2.1.4-070223\csla20vb\csla20vb\Csla\BusinessBase.vb:line 166<BR>&nbsp;&nbsp; at PT.Library.Resource.Save() in C:\Dev\Resources\Books\CSLA\ProjectTrackerTest\PT.Library\Resource.vb:line 190<BR>&nbsp;&nbsp; at PTWin.ResourceEdit.SaveResource(Boolean rebind)System.Runtime.Remoting.RemotingException: Server encountered an internal error. For more </FONT></P>
<P><FONT face="Courier New" size=2><FONT>information, turn off customErrors in the server's .config file.<BR></FONT>================</FONT></P>
<P><FONT face="Courier New" size=2>This is not a case when I'm using the Win client on the same machine (**) where data portal is hosted.<BR>&nbsp;<BR>For example when I try to concurrently update some data on machine (**) that has been already updated from machine (*) I've got a friendly message that </FONT></P>
<P><FONT face="Courier New" size=2>other user already change the data, but when I update data from machine (*) and data was changed from machine (**) I receive the error displayed above.</FONT></P>
<P><FONT face="Courier New" size=2>What is the problem am I missing something. I'm receiving this error on machine (*) very often, what should I do?</FONT></P>
<P><FONT face="Courier New" size=2>Regards<BR>vasil<BR></FONT></P></div><p style='font-size:small'>Copyright (c) Marimer LLC</body></html>
