<html><header><title>BusinessException returns DataPortalException</title></header><body><div style='float:right'><a href='http://cslanet.com'><img src='https://github.com/MarimerLLC/csla/raw/master/Support/Logos/csla%20win8_compact_s.png'/></a></div><p><h1>BusinessException returns DataPortalException</h1><span style='font-size:small'>Old forum URL: forums.lhotka.net/forums/t/5858.aspx</span></p><hr><div style='padding:0 15 3 15;background-color:powderblue'><h2>rasupit posted on Sunday, November 23, 2008</h2>I found that exception thrown from child object may not shown in BusinessException. This issue may occur when child data access code is called through automatic child data portal invoker DataPortal.UpdateChild.<br><br>With this scenario, we may have nested DataPortalException which make accessing the actual exception would not be as easy as InnerException.InnerException.<br><br>The fix I think is to walk in the exception tree for the last DataPortalException &gt; CallMethodException occurance.<br><br>Ricky<br></div><p style='font-size:small'>Copyright (c) Marimer LLC</body></html>
